<?xml version="1.0" encoding="utf-8"?>
<testsuites>
        <testsuite name="pytest" errors="0" failures="1" skipped="0" tests="1" time="13.806"
                timestamp="2024-09-12T10:28:22.783393+00:00" hostname="42b875a3388c">
                <testcase
                        classname="tests.system.providers.microsoft.fabric.example_fabric_item_run"
                        name="test_run" time="9.725">
                        <failure
                                message="AssertionError: The system test failed, please look at the logs to find out the underlying failed task(s)">def
                                test_run():
                                dag.on_failure_callback = add_callback(dag.on_failure_callback,
                                callback)
                                dag.on_success_callback = add_callback(dag.on_success_callback,
                                callback)
                                # If the env variable ``_AIRFLOW__SYSTEM_TEST_USE_EXECUTOR`` is set,
                                then use an executor to run the
                                # DAG
                                dag_run =
                                dag.test(use_executor=os.environ.get("_AIRFLOW__SYSTEM_TEST_USE_EXECUTOR")
                                == "1")
                                &gt; assert (
                                dag_run.state == DagRunState.SUCCESS
                                ), "The system test failed, please look at the logs to find out the
                                underlying failed task(s)"
                                E AssertionError: The system test failed, please look at the logs to
                                find out the underlying failed task(s)
                                tests/system/utils/__init__.py:64: AssertionError</failure>
                </testcase>
                <testcase
                        classname="tests.system.providers.microsoft.fabric.example_fabric_item_run"
                        name="test_run" time="9.725">
                        <failure
                                message="AssertionError: The system test failed, please look at the logs to find out the underlying failed task(s)">def
                                test_run():
                                dag.on_failure_callback = add_callback(dag.on_failure_callback,
                                callback)
                                dag.on_success_callback = add_callback(dag.on_success_callback,
                                callback)
                                # If the env variable ``_AIRFLOW__SYSTEM_TEST_USE_EXECUTOR`` is set,
                                then use an executor to run the
                                # DAG
                                dag_run =
                                dag.test(use_executor=os.environ.get("_AIRFLOW__SYSTEM_TEST_USE_EXECUTOR")
                                == "1")
                                &gt; assert (
                                dag_run.state == DagRunState.SUCCESS
                                ), "The system test failed, please look at the logs to find out the
                                underlying failed task(s)"
                                E AssertionError: The system test failed, please look at the logs to
                                find out the underlying failed task(s)
                                tests/system/utils/__init__.py:64: AssertionError</failure>
                </testcase>
        </testsuite>
</testsuites>